<?xml version="1.0" ?>
<!-- =================================================================================== -->
<!-- |    This document was autogenerated by xacro from lion.xacro                     | -->
<!-- |    EDITING THIS FILE BY HAND IS NOT RECOMMENDED                                 | -->
<!-- =================================================================================== -->
<!-- This URDF was automatically created by SolidWorks to URDF Exporter! Originally created by Stephen Brawner (brawner@gmail.com) 
     Commit Version: 1.6.0-4-g7f85cfe  Build Version: 1.6.7995.38578
     For more information, please see http://wiki.ros.org/sw_urdf_exporter -->
<robot name="lion">
  <link name="base_link">
    <inertial>
      <origin rpy="0 0 0" xyz="0.00178 0.004711 -0.007006"/>
      <mass value="8.286"/>
      <inertia ixx="0.056529" ixy="-0.001107" ixz="-3.045E-05" iyy="0.14156" iyz="-0.0011531" izz="0.17939"/>
    </inertial>
    <visual>
      <origin rpy="0 0 0" xyz="0 0 0"/>
      <geometry>
        <mesh filename="../meshes/base_link.STL"/>
      </geometry>
      <material name="">
        <color rgba="1 1 1 1"/>
      </material>
    </visual>
    <collision>
      <origin rpy="0 0 0" xyz="0 0 0"/>
      <geometry>
        <mesh filename="../meshes/base_link.STL"/>
      </geometry>
    </collision>
  </link>
  <link name="LegFR_hip">
    <inertial>
      <origin rpy="0 0 0" xyz="-0.005149 -0.04712 4.2E-05"/>
      <mass value="1.095"/>
      <inertia ixx="0.0010035" ixy="-0.00021789" ixz="1.433E-06" iyy="0.0014762" iyz="1.005E-06" izz="0.0012507"/>
    </inertial>
    <visual>
      <origin rpy="0 0 0" xyz="0 0 0"/>
      <geometry>
        <mesh filename="../meshes/hip_link.STL"/>
      </geometry>
      <material name="">
        <color rgba="1 1 1 1"/>
      </material>
    </visual>
    <collision>
      <origin rpy="0 0 0" xyz="0 0 0"/>
      <geometry>
        <mesh filename="../meshes/hip_link.STL"/>
      </geometry>
    </collision>
  </link>
  <joint name="JointFR_abad" type="revolute">
    <origin rpy="0.0 0.0 0" xyz="0.2467 -0.09 0.0005"/>
    <parent link="base_link"/>
    <child link="LegFR_hip"/>
    <axis xyz="1 0 0"/>
    <limit effort="30" lower="-1" upper="1" velocity="20"/>
 
  </joint>
  <link name="LegFR_thigh">
    <inertial>
      <origin rpy="0 0 0" xyz="-3.2E-05 -0.089075 -0.23824"/>
      <mass value="1.556"/>
      <inertia ixx="0.015631" ixy="-8.61E-07" ixz="-6.078E-06" iyy="0.016183" iyz="0.0004689" izz="0.0011163"/>
    </inertial>
    <visual>
      <origin rpy="0 0 0" xyz="0 0 0"/>
      <geometry>
        <mesh filename="../meshes/thigh_link.STL"/>
      </geometry>
      <material name="">
        <color rgba="1 1 1 1"/>
      </material>
    </visual>
    <collision>
      <origin rpy="0 0 0" xyz="0 0 0"/>
      <geometry>
        <mesh filename="../meshes/thigh_link.STL"/>
      </geometry>
    </collision>
  </link>
  <joint name="JointFR_hip" type="revolute">
    <origin rpy="0 0.0 0" xyz="0 0 0"/>
    <parent link="LegFR_hip"/>
    <child link="LegFR_thigh"/>
    <axis xyz="0 1 0"/>
    <limit effort="30" lower="-2" upper="2" velocity="20"/>

  </joint>
  <link name="LegFR_shank">
    <inertial>
      <origin rpy="0 0 0" xyz="-0.000122 -0.005126 -0.12406"/>
      <mass value="0.233"/>
      <inertia ixx="0.0033053" ixy="-3.64E-07" ixz="4.028E-06" iyy="0.0033126" iyz="-0.00013194" izz="4.3236E-05"/>
    </inertial>
    <visual>
      <origin rpy="0 0 0" xyz="0 0 0"/>
      <geometry>
        <mesh filename="../meshes/shank_link.STL"/>
      </geometry>
      <material name="">
        <color rgba="1 1 1 1"/>
      </material>
    </visual>
    <collision>
      <origin rpy="0 0 0" xyz="0 0 0"/>
      <geometry>
        <mesh filename="../meshes/shank_link.STL"/>
      </geometry>
    </collision>
  </link>
  <joint name="JointFR_knee" type="revolute">
    <origin rpy="0 0 0" xyz="0 -0.119 -0.3"/>
    <parent link="LegFR_thigh"/>
    <child link="LegFR_shank"/>
    <axis xyz="0 1 0"/>
    <limit effort="30" lower="-3" upper="3" velocity="20"/>

  </joint>
  <link name="LegFL_hip">
    <inertial>
      <origin rpy="0 0 0" xyz="-0.005149 -0.04712 4.2E-05"/>
      <mass value="1.095"/>
      <inertia ixx="0.0010035" ixy="-0.00021789" ixz="1.433E-06" iyy="0.0014762" iyz="1.005E-06" izz="0.0012507"/>
    </inertial>
    <visual>
      <origin rpy="0 0 0" xyz="0 0 0"/>
      <geometry>
        <mesh filename="../meshes/hip_link.STL"/>
      </geometry>
      <material name="">
        <color rgba="1 1 1 1"/>
      </material>
    </visual>
    <collision>
      <origin rpy="0 0 0" xyz="0 0 0"/>
      <geometry>
        <mesh filename="../meshes/hip_link.STL"/>
      </geometry>
    </collision>
  </link>
  <joint name="JointFL_abad" type="revolute">
    <origin rpy="3.141592653589793 0.0 0" xyz="0.2467 0.09 0.0005"/>
    <parent link="base_link"/>
    <child link="LegFL_hip"/>
    <axis xyz="1 0 0"/>
    <limit effort="30" lower="-1" upper="1" velocity="20"/>

  </joint>
  <link name="LegFL_thigh">
    <inertial>
      <origin rpy="0 0 0" xyz="-3.2E-05 -0.089075 -0.23824"/>
      <mass value="1.556"/>
      <inertia ixx="0.015631" ixy="-8.61E-07" ixz="-6.078E-06" iyy="0.016183" iyz="0.0004689" izz="0.0011163"/>
    </inertial>
    <visual>
      <origin rpy="0 0 0" xyz="0 0 0"/>
      <geometry>
        <mesh filename="../meshes/thigh_link.STL"/>
      </geometry>
      <material name="">
        <color rgba="1 1 1 1"/>
      </material>
    </visual>
    <collision>
      <origin rpy="0 0 0" xyz="0 0 0"/>
      <geometry>
        <mesh filename="../meshes/thigh_link.STL"/>
      </geometry>
    </collision>
  </link>
  <joint name="JointFL_hip" type="revolute">
    <origin rpy="0 3.141592653589793 0" xyz="0 0 0"/>
    <parent link="LegFL_hip"/>
    <child link="LegFL_thigh"/>
    <axis xyz="0 -1 0"/>
    <limit effort="30" lower="-2" upper="2" velocity="20"/>

  </joint>
  <link name="LegFL_shank">
    <inertial>
      <origin rpy="0 0 0" xyz="-0.000122 -0.005126 -0.12406"/>
      <mass value="0.233"/>
      <inertia ixx="0.0033053" ixy="-3.64E-07" ixz="4.028E-06" iyy="0.0033126" iyz="-0.00013194" izz="4.3236E-05"/>
    </inertial>
    <visual>
      <origin rpy="0 0 0" xyz="0 0 0"/>
      <geometry>
        <mesh filename="../meshes/shank_link.STL"/>
      </geometry>
      <material name="">
        <color rgba="1 1 1 1"/>
      </material>
    </visual>
    <collision>
      <origin rpy="0 0 0" xyz="0 0 0"/>
      <geometry>
        <mesh filename="../meshes/shank_link.STL"/>
      </geometry>
    </collision>
  </link>
  <joint name="JointFL_knee" type="revolute">
    <origin rpy="0 0 0" xyz="0 -0.119 -0.3"/>
    <parent link="LegFL_thigh"/>
    <child link="LegFL_shank"/>
    <axis xyz="0 -1 0"/>
    <limit effort="30" lower="-3" upper="3" velocity="20"/>

  </joint>
  <link name="LegHR_hip">
    <inertial>
      <origin rpy="0 0 0" xyz="-0.005149 -0.04712 4.2E-05"/>
      <mass value="1.095"/>
      <inertia ixx="0.0010035" ixy="-0.00021789" ixz="1.433E-06" iyy="0.0014762" iyz="1.005E-06" izz="0.0012507"/>
    </inertial>
    <visual>
      <origin rpy="0 0 0" xyz="0 0 0"/>
      <geometry>
        <mesh filename="../meshes/hip_link.STL"/>
      </geometry>
      <material name="">
        <color rgba="1 1 1 1"/>
      </material>
    </visual>
    <collision>
      <origin rpy="0 0 0" xyz="0 0 0"/>
      <geometry>
        <mesh filename="../meshes/hip_link.STL"/>
      </geometry>
    </collision>
  </link>
  <joint name="JointHR_abad" type="revolute">
    <origin rpy="0.0 3.141592653589793 0" xyz="-0.2467 -0.09 0.0005"/>
    <parent link="base_link"/>
    <child link="LegHR_hip"/>
    <axis xyz="-1 0 0"/>
    <limit effort="30" lower="-1" upper="1" velocity="20"/>

  </joint>
  <link name="LegHR_thigh">
    <inertial>
      <origin rpy="0 0 0" xyz="-3.2E-05 -0.089075 -0.23824"/>
      <mass value="1.556"/>
      <inertia ixx="0.015631" ixy="-8.61E-07" ixz="-6.078E-06" iyy="0.016183" iyz="0.0004689" izz="0.0011163"/>
    </inertial>
    <visual>
      <origin rpy="0 0 0" xyz="0 0 0"/>
      <geometry>
        <mesh filename="../meshes/thigh_link.STL"/>
      </geometry>
      <material name="">
        <color rgba="1 1 1 1"/>
      </material>
    </visual>
    <collision>
      <origin rpy="0 0 0" xyz="0 0 0"/>
      <geometry>
        <mesh filename="../meshes/thigh_link.STL"/>
      </geometry>
    </collision>
  </link>
  <joint name="JointHR_hip" type="revolute">
    <origin rpy="0 3.141592653589793 0" xyz="0 0 0"/>
    <parent link="LegHR_hip"/>
    <child link="LegHR_thigh"/>
    <axis xyz="0 1 0"/>
    <limit effort="30" lower="-2" upper="2" velocity="20"/>

  </joint>
  <link name="LegHR_shank">
    <inertial>
      <origin rpy="0 0 0" xyz="-0.000122 -0.005126 -0.12406"/>
      <mass value="0.233"/>
      <inertia ixx="0.0033053" ixy="-3.64E-07" ixz="4.028E-06" iyy="0.0033126" iyz="-0.00013194" izz="4.3236E-05"/>
    </inertial>
    <visual>
      <origin rpy="0 0 0" xyz="0 0 0"/>
      <geometry>
        <mesh filename="../meshes/shank_link.STL"/>
      </geometry>
      <material name="">
        <color rgba="1 1 1 1"/>
      </material>
    </visual>
    <collision>
      <origin rpy="0 0 0" xyz="0 0 0"/>
      <geometry>
        <mesh filename="../meshes/shank_link.STL"/>
      </geometry>
    </collision>
  </link>
  <joint name="JointHR_knee" type="revolute">
    <origin rpy="0 0 0" xyz="0 -0.119 -0.3"/>
    <parent link="LegHR_thigh"/>
    <child link="LegHR_shank"/>
    <axis xyz="0 1 0"/>
    <limit effort="30" lower="-3" upper="3" velocity="20"/>

  </joint>
  <link name="LegHL_hip">
    <inertial>
      <origin rpy="0 0 0" xyz="-0.005149 -0.04712 4.2E-05"/>
      <mass value="1.095"/>
      <inertia ixx="0.0010035" ixy="-0.00021789" ixz="1.433E-06" iyy="0.0014762" iyz="1.005E-06" izz="0.0012507"/>
    </inertial>
    <visual>
      <origin rpy="0 0 0" xyz="0 0 0"/>
      <geometry>
        <mesh filename="../meshes/hip_link.STL"/>
      </geometry>
      <material name="">
        <color rgba="1 1 1 1"/>
      </material>
    </visual>
    <collision>
      <origin rpy="0 0 0" xyz="0 0 0"/>
      <geometry>
        <mesh filename="../meshes/hip_link.STL"/>
      </geometry>
    </collision>
  </link>
  <joint name="JointHL_abad" type="revolute">
    <origin rpy="3.141592653589793 3.141592653589793 0" xyz="-0.2467 0.09 0.0005"/>
    <parent link="base_link"/>
    <child link="LegHL_hip"/>
    <axis xyz="-1 0 0"/>
    <limit effort="30" lower="-1" upper="1" velocity="20"/>

  </joint>
  <link name="LegHL_thigh">
    <inertial>
      <origin rpy="0 0 0" xyz="-3.2E-05 -0.089075 -0.23824"/>
      <mass value="1.556"/>
      <inertia ixx="0.015631" ixy="-8.61E-07" ixz="-6.078E-06" iyy="0.016183" iyz="0.0004689" izz="0.0011163"/>
    </inertial>
    <visual>
      <origin rpy="0 0 0" xyz="0 0 0"/>
      <geometry>
        <mesh filename="../meshes/thigh_link.STL"/>
      </geometry>
      <material name="">
        <color rgba="1 1 1 1"/>
      </material>
    </visual>
    <collision>
      <origin rpy="0 0 0" xyz="0 0 0"/>
      <geometry>
        <mesh filename="../meshes/thigh_link.STL"/>
      </geometry>
    </collision>
  </link>
  <joint name="JointHL_hip" type="revolute">
    <origin rpy="0 6.283185307179586 0" xyz="0 0 0"/>
    <parent link="LegHL_hip"/>
    <child link="LegHL_thigh"/>
    <axis xyz="0 -1 0"/>
    <limit effort="30" lower="-2" upper="2" velocity="20"/>

  </joint>
  <link name="LegHL_shank">
    <inertial>
      <origin rpy="0 0 0" xyz="-0.000122 -0.005126 -0.12406"/>
      <mass value="0.233"/>
      <inertia ixx="0.0033053" ixy="-3.64E-07" ixz="4.028E-06" iyy="0.0033126" iyz="-0.00013194" izz="4.3236E-05"/>
    </inertial>
    <visual>
      <origin rpy="0 0 0" xyz="0 0 0"/>
      <geometry>
        <mesh filename="../meshes/shank_link.STL"/>
      </geometry>
      <material name="">
        <color rgba="1 1 1 1"/>
      </material>
    </visual>
    <collision>
      <origin rpy="0 0 0" xyz="0 0 0"/>
      <geometry>
        <mesh filename="../meshes/shank_link.STL"/>
      </geometry>
    </collision>
  </link>
  <joint name="JointHL_knee" type="revolute">
    <origin rpy="0 0 0" xyz="0 -0.119 -0.3"/>
    <parent link="LegHL_thigh"/>
    <child link="LegHL_shank"/>
    <axis xyz="0 -1 0"/>
    <limit effort="30" lower="-3" upper="3" velocity="20"/>

  </joint>
</robot>

